Workbook

Sheet Counts (4-state)
A1: EV-Eye GT-frame 4-state classification — counts per subject (both eyes)
A2: State rule (I-VT): speed>493 px/s → Saccade(saccade-session)/Reset(smooth-session); else Fixation/Smooth. Source: cache/velocity_at_gt.csv (9,011 GT frames; 8,982 with speed).
A4: Subject | B4: Motion | F4: Total
B5: Fixation | C5: Saccade | D5: Smooth | E5: Reset
A6: 1 | B6: 87 | C6: 10 | D6: 97 | E6: 9 | F6: =SUM(B6:E6) -> 203
A7: 2 | B7: 124 | C7: 0 | D7: 110 | E7: 1 | F7: =SUM(B7:E7) -> 235
A8: 3 | B8: 82 | C8: 3 | D8: 79 | E8: 3 | F8: =SUM(B8:E8) -> 167
A9: 4 | B9: 88 | C9: 10 | D9: 87 | E9: 11 | F9: =SUM(B9:E9) -> 196
A10: 5 | B10: 75 | C10: 12 | D10: 70 | E10: 9 | F10: =SUM(B10:E10) -> 166
A11: 6 | B11: 90 | C11: 6 | D11: 96 | E11: 4 | F11: =SUM(B11:E11) -> 196
A12: 7 | B12: 90 | C12: 9 | D12: 99 | E12: 3 | F12: =SUM(B12:E12) -> 201
A13: 8 | B13: 93 | C13: 6 | D13: 95 | E13: 5 | F13: =SUM(B13:E13) -> 199
A14: 9 | B14: 92 | C14: 4 | D14: 107 | E14: 0 | F14: =SUM(B14:E14) -> 203
A15: 10 | B15: 89 | C15: 5 | D15: 81 | E15: 15 | F15: =SUM(B15:E15) -> 190
A16: 11 | B16: 80 | C16: 12 | D16: 108 | E16: 5 | F16: =SUM(B16:E16) -> 205
A17: 12 | B17: 86 | C17: 9 | D17: 98 | E17: 15 | F17: =SUM(B17:E17) -> 208
... A53: 48 | B53: 78 | C53: 0 | D53: 101 | E53: 1 | F53: =SUM(B53:E53) -> 180
A54: All | B54: =SUM(B6:B53) -> 3868 | C54: =SUM(C6:C53) -> 430 | D54: =SUM(D6:D53) -> 4301 | E54: =SUM(E6:E53) -> 383 | F54: =SUM(B54:E54) -> 8982

Sheet Share % (4-state)
A1: Per-subject 4-state share (% of subject's GT frames)
A3: Subject | B3: Fixation | C3: Saccade | D3: Smooth | E3: Reset | F3: Total
A4: 1 | B4: ='Counts (4-state)'!B6/'Counts (4-state)'!$F$6 -> 0.42857143 | C4: ='Counts (4-state)'!C6/'Counts (4-state)'!$F$6 -> 0.049261084 | D4: ='Counts (4-state)'!D6/'Counts (4-state)'!$F$6 -> 0.47783251 | E4: ='Counts (4-state)'!E6/'Counts (4-state)'!$F$6 -> 0.044334975 | F4: =SUM(B4:E4) -> 1
A5: 2 | B5: ='Counts (4-state)'!B7/'Counts (4-state)'!$F$7 -> 0.52765957 | C5: ='Counts (4-state)'!C7/'Counts (4-state)'!$F$7 -> 0 | D5: ='Counts (4-state)'!D7/'Counts (4-state)'!$F$7 -> 0.46808511 | E5: ='Counts (4-state)'!E7/'Counts (4-state)'!$F$7 -> 0.0042553191 | F5: =SUM(B5:E5) -> 1
A6: 3 | B6: ='Counts (4-state)'!B8/'Counts (4-state)'!$F$8 -> 0.49101796 | C6: ='Counts (4-state)'!C8/'Counts (4-state)'!$F$8 -> 0.017964072 | D6: ='Counts (4-state)'!D8/'Counts (4-state)'!$F$8 -> 0.47305389 | E6: ='Counts (4-state)'!E8/'Counts (4-state)'!$F$8 -> 0.017964072 | F6: =SUM(B6:E6) -> 1
A7: 4 | B7: ='Counts (4-state)'!B9/'Counts (4-state)'!$F$9 -> 0.44897959 | C7: ='Counts (4-state)'!C9/'Counts (4-state)'!$F$9 -> 0.051020408 | D7: ='Counts (4-state)'!D9/'Counts (4-state)'!$F$9 -> 0.44387755 | E7: ='Counts (4-state)'!E9/'Counts (4-state)'!$F$9 -> 0.056122449 | F7: =SUM(B7:E7) -> 1
A8: 5 | B8: ='Counts (4-state)'!B10/'Counts (4-state)'!$F$10 -> 0.45180723 | C8: ='Counts (4-state)'!C10/'Counts (4-state)'!$F$10 -> 0.072289157 | D8: ='Counts (4-state)'!D10/'Counts (4-state)'!$F$10 -> 0.42168675 | E8: ='Counts (4-state)'!E10/'Counts (4-state)'!$F$10 -> 0.054216867 | F8: =SUM(B8:E8) -> 1
A9: 6 | B9: ='Counts (4-state)'!B11/'Counts (4-state)'!$F$11 -> 0.45918367 | C9: ='Counts (4-state)'!C11/'Counts (4-state)'!$F$11 -> 0.030612245 | D9: ='Counts (4-state)'!D11/'Counts (4-state)'!$F$11 -> 0.48979592 | E9: ='Counts (4-state)'!E11/'Counts (4-state)'!$F$11 -> 0.020408163 | F9: =SUM(B9:E9) -> 1
A10: 7 | B10: ='Counts (4-state)'!B12/'Counts (4-state)'!$F$12 -> 0.44776119 | C10: ='Counts (4-state)'!C12/'Counts (4-state)'!$F$12 -> 0.044776119 | D10: ='Counts (4-state)'!D12/'Counts (4-state)'!$F$12 -> 0.49253731 | E10: ='Counts (4-state)'!E12/'Counts (4-state)'!$F$12 -> 0.014925373 | F10: =SUM(B10:E10) -> 1
A11: 8 | B11: ='Counts (4-state)'!B13/'Counts (4-state)'!$F$13 -> 0.46733668 | C11: ='Counts (4-state)'!C13/'Counts (4-state)'!$F$13 -> 0.030150754 | D11: ='Counts (4-state)'!D13/'Counts (4-state)'!$F$13 -> 0.47738693 | E11: ='Counts (4-state)'!E13/'Counts (4-state)'!$F$13 -> 0.025125628 | F11: =SUM(B11:E11) -> 1
A12: 9 | B12: ='Counts (4-state)'!B14/'Counts (4-state)'!$F$14 -> 0.45320197 | C12: ='Counts (4-state)'!C14/'Counts (4-state)'!$F$14 -> 0.019704433 | D12: ='Counts (4-state)'!D14/'Counts (4-state)'!$F$14 -> 0.5270936 | E12: ='Counts (4-state)'!E14/'Counts (4-state)'!$F$14 -> 0 | F12: =SUM(B12:E12) -> 1
A13: 10 | B13: ='Counts (4-state)'!B15/'Counts (4-state)'!$F$15 -> 0.46842105 | C13: ='Counts (4-state)'!C15/'Counts (4-state)'!$F$15 -> 0.026315789 | D13: ='Counts (4-state)'!D15/'Counts (4-state)'!$F$15 -> 0.42631579 | E13: ='Counts (4-state)'!E15/'Counts (4-state)'!$F$15 -> 0.078947368 | F13: =SUM(B13:E13) -> 1
A14: 11 | B14: ='Counts (4-state)'!B16/'Counts (4-state)'!$F$16 -> 0.3902439 | C14: ='Counts (4-state)'!C16/'Counts (4-state)'!$F$16 -> 0.058536585 | D14: ='Counts (4-state)'!D16/'Counts (4-state)'!$F$16 -> 0.52682927 | E14: ='Counts (4-state)'!E16/'Counts (4-state)'!$F$16 -> 0.024390244 | F14: =SUM(B14:E14) -> 1
A15: 12 | B15: ='Counts (4-state)'!B17/'Counts (4-state)'!$F$17 -> 0.41346154 | C15: ='Counts (4-state)'!C17/'Counts (4-state)'!$F$17 -> 0.043269231 | D15: ='Counts (4-state)'!D17/'Counts (4-state)'!$F$17 -> 0.47115385 | E15: ='Counts (4-state)'!E17/'Counts (4-state)'!$F$17 -> 0.072115385 | F15: =SUM(B15:E15) -> 1
A16: 13 | B16: ='Counts (4-state)'!B18/'Counts (4-state)'!$F$18 -> 0.40952381 | C16: ='Counts (4-state)'!C18/'Counts (4-state)'!$F$18 -> 0.061904762 | D16: ='Counts (4-state)'!D18/'Counts (4-state)'!$F$18 -> 0.46666667 | E16: ='Counts (4-state)'!E18/'Counts (4-state)'!$F$18 -> 0.061904762 | F16: =SUM(B16:E16) -> 1
A17: 14 | B17: ='Counts (4-state)'!B19/'Counts (4-state)'!$F$19 -> 0.43589744 | C17: ='Counts (4-state)'!C19/'Counts (4-state)'!$F$19 -> 0.056410256 | D17: ='Counts (4-state)'!D19/'Counts (4-state)'!$F$19 -> 0.48205128 | E17: ='Counts (4-state)'!E19/'Counts (4-state)'!$F$19 -> 0.025641026 | F17: =SUM(B17:E17) -> 1
A18: 15 | B18: ='Counts (4-state)'!B20/'Counts (4-state)'!$F$20 -> 0.46703297 | C18: ='Counts (4-state)'!C20/'Counts (4-state)'!$F$20 -> 0.043956044 | D18: ='Counts (4-state)'!D20/'Counts (4-state)'!$F$20 -> 0.40659341 | E18: ='Counts (4-state)'!E20/'Counts (4-state)'!$F$20 -> 0.082417582 | F18: =SUM(B18:E18) -> 1
A19: 16 | B19: ='Counts (4-state)'!B21/'Counts (4-state)'!$F$21 -> 0.37988827 | C19: ='Counts (4-state)'!C21/'Counts (4-state)'!$F$21 -> 0.10055866 | D19: ='Counts (4-state)'!D21/'Counts (4-state)'!$F$21 -> 0.48603352 | E19: ='Counts (4-state)'!E21/'Counts (4-state)'!$F$21 -> 0.033519553 | F19: =SUM(B19:E19) -> 1
A20: 17 | B20: ='Counts (4-state)'!B22/'Counts (4-state)'!$F$22 -> 0.38953488 | C20: ='Counts (4-state)'!C22/'Counts (4-state)'!$F$22 -> 0.10465116 | D20: ='Counts (4-state)'!D22/'Counts (4-state)'!$F$22 -> 0.36046512 | E20: ='Counts (4-state)'!E22/'Counts (4-state)'!$F$22 -> 0.14534884 | F20: =SUM(B20:E20) -> 1
A21: 18 | B21: ='Counts (4-state)'!B23/'Counts (4-state)'!$F$23 -> 0.35964912 | C21: ='Counts (4-state)'!C23/'Counts (4-state)'!$F$23 -> 0.026315789 | D21: ='Counts (4-state)'!D23/'Counts (4-state)'!$F$23 -> 0.56140351 | E21: ='Counts (4-state)'!E23/'Counts (4-state)'!$F$23 -> 0.052631579 | F21: =SUM(B21:E21) -> 1
A22: 19 | B22: ='Counts (4-state)'!B24/'Counts (4-state)'!$F$24 -> 0.46039604 | C22: ='Counts (4-state)'!C24/'Counts (4-state)'!$F$24 -> 0.024752475 | D22: ='Counts (4-state)'!D24/'Counts (4-state)'!$F$24 -> 0.4950495 | E22: ='Counts (4-state)'!E24/'Counts (4-state)'!$F$24 -> 0.01980198 | F22: =SUM(B22:E22) -> 1
A23: 20 | B23: ='Counts (4-state)'!B25/'Counts (4-state)'!$F$25 -> 0.36065574 | C23: ='Counts (4-state)'!C25/'Counts (4-state)'!$F$25 -> 0.081967213 | D23: ='Counts (4-state)'!D25/'Counts (4-state)'!$F$25 -> 0.45901639 | E23: ='Counts (4-state)'!E25/'Counts (4-state)'!$F$25 -> 0.098360656 | F23: =SUM(B23:E23) -> 1
A24: 21 | B24: ='Counts (4-state)'!B26/'Counts (4-state)'!$F$26 -> 0.48421053 | C24: ='Counts (4-state)'!C26/'Counts (4-state)'!$F$26 -> 0.063157895 | D24: ='Counts (4-state)'!D26/'Counts (4-state)'!$F$26 -> 0.41052632 | E24: ='Counts (4-state)'!E26/'Counts (4-state)'!$F$26 -> 0.042105263 | F24: =SUM(B24:E24) -> 1
A25: 22 | B25: ='Counts (4-state)'!B27/'Counts (4-state)'!$F$27 -> 0.44670051 | C25: ='Counts (4-state)'!C27/'Counts (4-state)'!$F$27 -> 0.015228426 | D25: ='Counts (4-state)'!D27/'Counts (4-state)'!$F$27 -> 0.48730964 | E25: ='Counts (4-state)'!E27/'Counts (4-state)'!$F$27 -> 0.050761421 | F25: =SUM(B25:E25) -> 1
A26: 23 | B26: ='Counts (4-state)'!B28/'Counts (4-state)'!$F$28 -> 0.4742268 | C26: ='Counts (4-state)'!C28/'Counts (4-state)'!$F$28 -> 0.010309278 | D26: ='Counts (4-state)'!D28/'Counts (4-state)'!$F$28 -> 0.49484536 | E26: ='Counts (4-state)'!E28/'Counts (4-state)'!$F$28 -> 0.020618557 | F26: =SUM(B26:E26) -> 1
A27: 24 | B27: ='Counts (4-state)'!B29/'Counts (4-state)'!$F$29 -> 0.43137255 | C27: ='Counts (4-state)'!C29/'Counts (4-state)'!$F$29 -> 0.013071895 | D27: ='Counts (4-state)'!D29/'Counts (4-state)'!$F$29 -> 0.55555556 | E27: ='Counts (4-state)'!E29/'Counts (4-state)'!$F$29 -> 0 | F27: =SUM(B27:E27) -> 1
A28: 25 | B28: ='Counts (4-state)'!B30/'Counts (4-state)'!$F$30 -> 0.42424242 | C28: ='Counts (4-state)'!C30/'Counts (4-state)'!$F$30 -> 0.060606061 | D28: ='Counts (4-state)'!D30/'Counts (4-state)'!$F$30 -> 0.47979798 | E28: ='Counts (4-state)'!E30/'Counts (4-state)'!$F$30 -> 0.035353535 | F28: =SUM(B28:E28) -> 1
A29: 26 | B29: ='Counts (4-state)'!B31/'Counts (4-state)'!$F$31 -> 0.40223464 | C29: ='Counts (4-state)'!C31/'Counts (4-state)'!$F$31 -> 0.10614525 | D29: ='Counts (4-state)'!D31/'Counts (4-state)'!$F$31 -> 0.48603352 | E29: ='Counts (4-state)'!E31/'Counts (4-state)'!$F$31 -> 0.0055865922 | F29: =SUM(B29:E29) -> 1
A30: 27 | B30: ='Counts (4-state)'!B32/'Counts (4-state)'!$F$32 -> 0.44973545 | C30: ='Counts (4-state)'!C32/'Counts (4-state)'!$F$32 -> 0.047619048 | D30: ='Counts (4-state)'!D32/'Counts (4-state)'!$F$32 -> 0.47089947 | E30: ='Counts (4-state)'!E32/'Counts (4-state)'!$F$32 -> 0.031746032 | F30: =SUM(B30:E30) -> 1
A31: 28 | B31: ='Counts (4-state)'!B33/'Counts (4-state)'!$F$33 -> 0.45918367 | C31: ='Counts (4-state)'!C33/'Counts (4-state)'!$F$33 -> 0.035714286 | D31: ='Counts (4-state)'!D33/'Counts (4-state)'!$F$33 -> 0.4744898 | E31: ='Counts (4-state)'!E33/'Counts (4-state)'!$F$33 -> 0.030612245 | F31: =SUM(B31:E31) -> 1
A32: 29 | B32: ='Counts (4-state)'!B34/'Counts (4-state)'!$F$34 -> 0.38728324 | C32: ='Counts (4-state)'!C34/'Counts (4-state)'!$F$34 -> 0.086705202 | D32: ='Counts (4-state)'!D34/'Counts (4-state)'!$F$34 -> 0.45086705 | E32: ='Counts (4-state)'!E34/'Counts (4-state)'!$F$34 -> 0.075144509 | F32: =SUM(B32:E32) -> 1
A33: 30 | B33: ='Counts (4-state)'!B35/'Counts (4-state)'!$F$35 -> 0.48756219 | C33: ='Counts (4-state)'!C35/'Counts (4-state)'!$F$35 -> 0 | D33: ='Counts (4-state)'!D35/'Counts (4-state)'!$F$35 -> 0.49751244 | E33: ='Counts (4-state)'!E35/'Counts (4-state)'!$F$35 -> 0.014925373 | F33: =SUM(B33:E33) -> 1
A34: 31 | B34: ='Counts (4-state)'!B36/'Counts (4-state)'!$F$36 -> 0.43523316 | C34: ='Counts (4-state)'!C36/'Counts (4-state)'!$F$36 -> 0.051813472 | D34: ='Counts (4-state)'!D36/'Counts (4-state)'!$F$36 -> 0.48704663 | E34: ='Counts (4-state)'!E36/'Counts (4-state)'!$F$36 -> 0.025906736 | F34: =SUM(B34:E34) -> 1
A35: 32 | B35: ='Counts (4-state)'!B37/'Counts (4-state)'!$F$37 -> 0.40410959 | C35: ='Counts (4-state)'!C37/'Counts (4-state)'!$F$37 -> 0.075342466 | D35: ='Counts (4-state)'!D37/'Counts (4-state)'!$F$37 -> 0.38356164 | E35: ='Counts (4-state)'!E37/'Counts (4-state)'!$F$37 -> 0.1369863 | F35: =SUM(B35:E35) -> 1
A36: 33 | B36: ='Counts (4-state)'!B38/'Counts (4-state)'!$F$38 -> 0.40654206 | C36: ='Counts (4-state)'!C38/'Counts (4-state)'!$F$38 -> 0.065420561 | D36: ='Counts (4-state)'!D38/'Counts (4-state)'!$F$38 -> 0.44859813 | E36: ='Counts (4-state)'!E38/'Counts (4-state)'!$F$38 -> 0.079439252 | F36: =SUM(B36:E36) -> 1
A37: 34 | B37: ='Counts (4-state)'!B39/'Counts (4-state)'!$F$39 -> 0.41836735 | C37: ='Counts (4-state)'!C39/'Counts (4-state)'!$F$39 -> 0.071428571 | D37: ='Counts (4-state)'!D39/'Counts (4-state)'!$F$39 -> 0.46428571 | E37: ='Counts (4-state)'!E39/'Counts (4-state)'!$F$39 -> 0.045918367 | F37: =SUM(B37:E37) -> 1
A38: 35 | B38: ='Counts (4-state)'!B40/'Counts (4-state)'!$F$40 -> 0.38317757 | C38: ='Counts (4-state)'!C40/'Counts (4-state)'!$F$40 -> 0.074766355 | D38: ='Counts (4-state)'!D40/'Counts (4-state)'!$F$40 -> 0.49065421 | E38: ='Counts (4-state)'!E40/'Counts (4-state)'!$F$40 -> 0.051401869 | F38: =SUM(B38:E38) -> 1
A39: 36 | B39: ='Counts (4-state)'!B41/'Counts (4-state)'!$F$41 -> 0.4 | C39: ='Counts (4-state)'!C41/'Counts (4-state)'!$F$41 -> 0.066666667 | D39: ='Counts (4-state)'!D41/'Counts (4-state)'!$F$41 -> 0.4952381 | E39: ='Counts (4-state)'!E41/'Counts (4-state)'!$F$41 -> 0.038095238 | F39: =SUM(B39:E39) -> 1
A40: 37 | B40: ='Counts (4-state)'!B42/'Counts (4-state)'!$F$42 -> 0.42045455 | C40: ='Counts (4-state)'!C42/'Counts (4-state)'!$F$42 -> 0.039772727 | D40: ='Counts (4-state)'!D42/'Counts (4-state)'!$F$42 -> 0.48295455 | E40: ='Counts (4-state)'!E42/'Counts (4-state)'!$F$42 -> 0.056818182 | F40: =SUM(B40:E40) -> 1
A41: 38 | B41: ='Counts (4-state)'!B43/'Counts (4-state)'!$F$43 -> 0.39153439 | C41: ='Counts (4-state)'!C43/'Counts (4-state)'!$F$43 -> 0.084656085 | D41: ='Counts (4-state)'!D43/'Counts (4-state)'!$F$43 -> 0.47089947 | E41: ='Counts (4-state)'!E43/'Counts (4-state)'!$F$43 -> 0.052910053 | F41: =SUM(B41:E41) -> 1
...

Sheet Definition & Validation
A1: EV-Eye 4-stage classification — definition, validation, limitations
A3: Stage definitions (per GT frame, I-VT velocity rule)
A4: Speed = cv2 dense-trajectory central difference (±2 frames) at each GT frame, px/s.
A5: Threshold v_sacc = 493 px/s (= 90th percentile of saccade-session speed; same as the validated 3-state pipeline).
A6: • Fixation = saccade-session (101/201) frame with speed ≤ v_sacc (holding gaze on a static dot).
A7: • Saccade = saccade-session frame with speed > v_sacc (fast jump to a new dot position).
A8: • Smooth = smooth-session (102/202) frame with speed ≤ v_sacc (tracking the continuously moving dot).
A9: • Reset = smooth-session frame with speed > v_sacc (fast return / catch-up saccade when the pursuit target jumps back).
A11: Why 'Reset' = high-speed in smooth sessions
A12: The smooth stimulus (Display_Dot_smooth.m) sweeps a dot in a serpentine raster and then restarts, forcing large
A13: return/catch-up saccades. In a pursuit session any high-speed eye movement is NOT pursuit, so it is the 'reset' phase.
A14: This simply splits the validated 3-state 'Saccade' bucket by session type → Saccade (saccade-session) + Reset (smooth-session).
... A27: 5. This is a FRAME-level classification of GT-annotated frames only (8,982 of 1.49M frames carry GT).
